<?xml version="1.0"?>
<robot name="simple_robot">
    <link name="base_link">
        <visual>
            <geometry>
                <box size="0.1 0.1 0.1"/>
            </geometry>
            <origin  xyz="0.0 0.0 0.05" rpy="0.0 0.0 0.0"/>
            <material name="red">
                <color rgba="1.0 0.0 0.0 1.0"/>
            </material>
        </visual>
    </link>
    <link name="link1">
        <visual>
            <geometry>
                <box size="0.1 0.1 0.1"/>
            </geometry>
            <origin  xyz="0.0 0.0 0.05" rpy="0.0 0.0 0.0"/>
            <material name="blue">
                <color rgba="0.0 0.0 0.1 1.0"/>
            </material>
        </visual>
    </link>
    <joint name="joint1" type="revolute">
        <parent link="base_link"/>
        <child link="link1"/>
        <origin xyz="0.0 0.0 0.1"/>
        <axis xyz="0.0 0.0 1.0"/>
        <limit lower="-1.57" upper="1.57" effort="10.0" velocity="1.0"/>
    </joint>
</robot>